Workbook

Sheet Plan_Exptl
A1: enabled | B1: sweep_id | C1: sample_id | D1: flow_type | E1: NK | F1: hK_star | G1: fe_model | H1: drag_model | I1: phi | J1: De | K1: folder | L1: out_root | M1: notes
A2: TRUE | B2: 1 | C2: G1 | D2: styext | E2: 30000 | F2: 0.005 | G2: fenepm | H2: constant | I2: 0.02 | J2: 1 | K2: gaillard | L2: julia/experiments/tnwpaper/outputs/exptl_comparison | M2: CANONICAL: Gaillard G1 (PEO-visc), c/c* Graessley, h*K=0.005
A3: TRUE | B3: 2 | C3: G1 | D3: styext | E3: 30000 | F3: 0.005 | G3: fenepm | H3: c2d2 | I3: 0.02 | J3: 1 | K3: gaillard | L3: julia/experiments/tnwpaper/outputs/exptl_comparison | M3: CANONICAL: Gaillard G1 (PEO-visc), c/c* Graessley, h*K=0.005
A4: TRUE | B4: 3 | C4: G1 | D4: caber | E4: 30000 | F4: 0.005 | G4: fenepm | H4: constant | I4: 0.02 | J4: [0.01, 0.03, 0.1, 0.3, 1, 3, 10, 30, 100] | K4: gaillard | L4: julia/experiments/tnwpaper/outputs/exptl_comparison | M4: CANONICAL: Gaillard G1 (PEO-visc), c/c* Graessley, h*K=0.005
A5: TRUE | B5: 4 | C5: G1 | D5: caber | E5: 30000 | F5: 0.005 | G5: fenepm | H5: c2d2 | I5: 0.02 | J5: [0.01, 0.03, 0.1, 0.3, 1, 3, 10, 30, 100] | K5: gaillard | L5: julia/experiments/tnwpaper/outputs/exptl_comparison | M5: CANONICAL: Gaillard G1 (PEO-visc), c/c* Graessley, h*K=0.005
A6: TRUE | B6: 5 | C6: A1 | D6: styext | E6: 2700 | F6: 0.01 | G6: fenepm | H6: constant | I6: 0.13 | J6: 1 | K6: anna | L6: julia/experiments/tnwpaper/outputs/exptl_comparison | M6: CANONICAL: Anna A1-A3, c/c* number-density, h*K=0.01
A7: TRUE | B7: 6 | C7: A1 | D7: styext | E7: 2700 | F7: 0.01 | G7: fenepm | H7: c2d2 | I7: 0.13 | J7: 1 | K7: anna | L7: julia/experiments/tnwpaper/outputs/exptl_comparison | M7: CANONICAL: Anna A1-A3, c/c* number-density, h*K=0.01
A8: TRUE | B8: 7 | C8: A1 | D8: caber | E8: 2700 | F8: 0.01 | G8: fenepm | H8: constant | I8: 0.13 | J8: [0.01, 0.03, 0.1, 0.3, 1, 3, 10, 30, 100, 300] | K8: anna | L8: julia/experiments/tnwpaper/outputs/exptl_comparison | M8: CANONICAL: Anna A1-A3, c/c* number-density, h*K=0.01
A9: TRUE | B9: 8 | C9: A1 | D9: caber | E9: 2700 | F9: 0.01 | G9: fenepm | H9: c2d2 | I9: 0.13 | J9: [0.01, 0.03, 0.1, 0.3, 1, 3, 10, 30, 100, 300] | K9: anna | L9: julia/experiments/tnwpaper/outputs/exptl_comparison | M9: CANONICAL: Anna A1-A3, c/c* number-density, h*K=0.01
A10: TRUE | B10: 9 | C10: A2 | D10: styext | E10: 8760 | F10: 0.01 | G10: fenepm | H10: constant | I10: 0.23 | J10: 1 | K10: anna | L10: julia/experiments/tnwpaper/outputs/exptl_comparison | M10: CANONICAL: Anna A1-A3, c/c* number-density, h*K=0.01
A11: TRUE | B11: 10 | C11: A2 | D11: styext | E11: 8760 | F11: 0.01 | G11: fenepm | H11: c2d2 | I11: 0.23 | J11: 1 | K11: anna | L11: julia/experiments/tnwpaper/outputs/exptl_comparison | M11: CANONICAL: Anna A1-A3, c/c* number-density, h*K=0.01
A12: TRUE | B12: 11 | C12: A2 | D12: caber | E12: 8760 | F12: 0.01 | G12: fenepm | H12: constant | I12: 0.23 | J12: [0.01, 0.03, 0.1, 0.3, 1, 3, 10, 30, 100, 300] | K12: anna | L12: julia/experiments/tnwpaper/outputs/exptl_comparison | M12: CANONICAL: Anna A1-A3, c/c* number-density, h*K=0.01
A13: TRUE | B13: 12 | C13: A2 | D13: caber | E13: 8760 | F13: 0.01 | G13: fenepm | H13: c2d2 | I13: 0.23 | J13: [0.01, 0.03, 0.1, 0.3, 1, 3, 10, 30, 100, 300] | K13: anna | L13: julia/experiments/tnwpaper/outputs/exptl_comparison | M13: CANONICAL: Anna A1-A3, c/c* number-density, h*K=0.01
A14: TRUE | B14: 13 | C14: A3 | D14: styext | E14: 27000 | F14: 0.01 | G14: fenepm | H14: constant | I14: 0.4 | J14: 1 | K14: anna | L14: julia/experiments/tnwpaper/outputs/exptl_comparison | M14: CANONICAL: Anna A1-A3, c/c* number-density, h*K=0.01
A15: TRUE | B15: 14 | C15: A3 | D15: styext | E15: 27000 | F15: 0.01 | G15: fenepm | H15: c2d2 | I15: 0.4 | J15: 1 | K15: anna | L15: julia/experiments/tnwpaper/outputs/exptl_comparison | M15: CANONICAL: Anna A1-A3, c/c* number-density, h*K=0.01
A16: TRUE | B16: 15 | C16: A3 | D16: caber | E16: 27000 | F16: 0.01 | G16: fenepm | H16: constant | I16: 0.4 | J16: [0.01, 0.03, 0.1, 0.3, 1, 3, 10, 30, 100, 300] | K16: anna | L16: julia/experiments/tnwpaper/outputs/exptl_comparison | M16: CANONICAL: Anna A1-A3, c/c* number-density, h*K=0.01
A17: TRUE | B17: 16 | C17: A3 | D17: caber | E17: 27000 | F17: 0.01 | G17: fenepm | H17: c2d2 | I17: 0.4 | J17: [0.01, 0.03, 0.1, 0.3, 1, 3, 10, 30, 100, 300] | K17: anna | L17: julia/experiments/tnwpaper/outputs/exptl_comparison | M17: CANONICAL: Anna A1-A3, c/c* number-density, h*K=0.01
A18: FALSE | B18: 17 | C18: C1 | D18: styext | E18: 11200 | F18: 0.04 | G18: fenepm | H18: constant | I18: 0.004 | J18: 1 | K18: clasen | L18: julia/experiments/tnwpaper/outputs/exptl_comparison | M18: SUPERSEDED: old Sample-E h*K=0.04 (use clasen_e_km@0.03)
A19: FALSE | B19: 18 | C19: C1 | D19: styext | E19: 11200 | F19: 0.04 | G19: fenepm | H19: c2d2 | I19: 0.004 | J19: 1 | K19: clasen | L19: julia/experiments/tnwpaper/outputs/exptl_comparison | M19: SUPERSEDED: old Sample-E h*K=0.04 (use clasen_e_km@0.03)
A20: FALSE | B20: 19 | C20: C1 | D20: caber | E20: 11200 | F20: 0.04 | G20: fenepm | H20: constant | I20: 0.004 | J20: [0.01, 0.03, 0.1, 0.3, 1, 3, 10, 30, 100] | K20: clasen | L20: julia/experiments/tnwpaper/outputs/exptl_comparison | M20: SUPERSEDED: old Sample-E h*K=0.04 (use clasen_e_km@0.03)
A21: FALSE | B21: 20 | C21: C1 | D21: caber | E21: 11200 | F21: 0.04 | G21: fenepm | H21: c2d2 | I21: 0.004 | J21: [0.01, 0.03, 0.1, 0.3, 1, 3, 10, 30, 100] | K21: clasen | L21: julia/experiments/tnwpaper/outputs/exptl_comparison | M21: SUPERSEDED: old Sample-E h*K=0.04 (use clasen_e_km@0.03)
A22: FALSE | B22: 21 | C22: C2 | D22: styext | E22: 11200 | F22: 0.04 | G22: fenepm | H22: constant | I22: 0.005 | J22: 1 | K22: clasen | L22: julia/experiments/tnwpaper/outputs/exptl_comparison | M22: SUPERSEDED: old Sample-E h*K=0.04 (use clasen_e_km@0.03)
A23: FALSE | B23: 22 | C23: C2 | D23: styext | E23: 11200 | F23: 0.04 | G23: fenepm | H23: c2d2 | I23: 0.005 | J23: 1 | K23: clasen | L23: julia/experiments/tnwpaper/outputs/exptl_comparison | M23: SUPERSEDED: old Sample-E h*K=0.04 (use clasen_e_km@0.03)
A24: FALSE | B24: 23 | C24: C2 | D24: caber | E24: 11200 | F24: 0.04 | G24: fenepm | H24: constant | I24: 0.005 | J24: [0.01, 0.03, 0.1, 0.3, 1, 3, 10, 30, 100] | K24: clasen | L24: julia/experiments/tnwpaper/outputs/exptl_comparison | M24: SUPERSEDED: old Sample-E h*K=0.04 (use clasen_e_km@0.03)
A25: FALSE | B25: 24 | C25: C2 | D25: caber | E25: 11200 | F25: 0.04 | G25: fenepm | H25: c2d2 | I25: 0.005 | J25: [0.01, 0.03, 0.1, 0.3, 1, 3, 10, 30, 100] | K25: clasen | L25: julia/experiments/tnwpaper/outputs/exptl_comparison | M25: SUPERSEDED: old Sample-E h*K=0.04 (use clasen_e_km@0.03)
A26: FALSE | B26: 25 | C26: C3 | D26: styext | E26: 11200 | F26: 0.04 | G26: fenepm | H26: constant | I26: 0.016 | J26: 1 | K26: clasen | L26: julia/experiments/tnwpaper/outputs/exptl_comparison | M26: SUPERSEDED: old Sample-E h*K=0.04 (use clasen_e_km@0.03)
A27: FALSE | B27: 26 | C27: C3 | D27: styext | E27: 11200 | F27: 0.04 | G27: fenepm | H27: c2d2 | I27: 0.016 | J27: 1 | K27: clasen | L27: julia/experiments/tnwpaper/outputs/exptl_comparison | M27: SUPERSEDED: old Sample-E h*K=0.04 (use clasen_e_km@0.03)
A28: FALSE | B28: 27 | C28: C3 | D28: caber | E28: 11200 | F28: 0.04 | G28: fenepm | H28: constant | I28: 0.016 | J28: [0.01, 0.03, 0.1, 0.3, 1, 3, 10, 30, 100] | K28: clasen | L28: julia/experiments/tnwpaper/outputs/exptl_comparison | M28: SUPERSEDED: old Sample-E h*K=0.04 (use clasen_e_km@0.03)
A29: FALSE | B29: 28 | C29: C3 | D29: caber | E29: 11200 | F29: 0.04 | G29: fenepm | H29: c2d2 | I29: 0.016 | J29: [0.01, 0.03, 0.1, 0.3, 1, 3, 10, 30, 100] | K29: clasen | L29: julia/experiments/tnwpaper/outputs/exptl_comparison | M29: SUPERSEDED: old Sample-E h*K=0.04 (use clasen_e_km@0.03)
A30: FALSE | B30: 29 | C30: C4 | D30: styext | E30: 11200 | F30: 0.04 | G30: fenepm | H30: constant | I30: 0.05 | J30: 1 | K30: clasen | L30: julia/experiments/tnwpaper/outputs/exptl_comparison | M30: SUPERSEDED: old Sample-E h*K=0.04 (use clasen_e_km@0.03)
A31: FALSE | B31: 30 | C31: C4 | D31: styext | E31: 11200 | F31: 0.04 | G31: fenepm | H31: c2d2 | I31: 0.05 | J31: 1 | K31: clasen | L31: julia/experiments/tnwpaper/outputs/exptl_comparison | M31: SUPERSEDED: old Sample-E h*K=0.04 (use clasen_e_km@0.03)
A32: FALSE | B32: 31 | C32: C4 | D32: caber | E32: 11200 | F32: 0.04 | G32: fenepm | H32: constant | I32: 0.05 | J32: [0.01, 0.03, 0.1, 0.3, 1, 3, 10, 30, 100] | K32: clasen | L32: julia/experiments/tnwpaper/outputs/exptl_comparison | M32: SUPERSEDED: old Sample-E h*K=0.04 (use clasen_e_km@0.03)
A33: FALSE | B33: 32 | C33: C4 | D33: caber | E33: 11200 | F33: 0.04 | G33: fenepm | H33: c2d2 | I33: 0.05 | J33: [0.01, 0.03, 0.1, 0.3, 1, 3, 10, 30, 100] | K33: clasen | L33: julia/experiments/tnwpaper/outputs/exptl_comparison | M33: SUPERSEDED: old Sample-E h*K=0.04 (use clasen_e_km@0.03)
A34: FALSE | B34: 33 | C34: C5 | D34: styext | E34: 11200 | F34: 0.04 | G34: fenepm | H34: constant | I34: 0.16 | J34: 1 | K34: clasen | L34: julia/experiments/tnwpaper/outputs/exptl_comparison | M34: SUPERSEDED: old Sample-E h*K=0.04 (use clasen_e_km@0.03)
A35: FALSE | B35: 34 | C35: C5 | D35: styext | E35: 11200 | F35: 0.04 | G35: fenepm | H35: c2d2 | I35: 0.16 | J35: 1 | K35: clasen | L35: julia/experiments/tnwpaper/outputs/exptl_comparison | M35: SUPERSEDED: old Sample-E h*K=0.04 (use clasen_e_km@0.03)
A36: FALSE | B36: 35 | C36: C5 | D36: caber | E36: 11200 | F36: 0.04 | G36: fenepm | H36: constant | I36: 0.16 | J36: [0.01, 0.03, 0.1, 0.3, 1, 3, 10, 30, 100] | K36: clasen | L36: julia/experiments/tnwpaper/outputs/exptl_comparison | M36: SUPERSEDED: old Sample-E h*K=0.04 (use clasen_e_km@0.03)
A37: FALSE | B37: 36 | C37: C5 | D37: caber | E37: 11200 | F37: 0.04 | G37: fenepm | H37: c2d2 | I37: 0.16 | J37: [0.01, 0.03, 0.1, 0.3, 1, 3, 10, 30, 100] | K37: clasen | L37: julia/experiments/tnwpaper/outputs/exptl_comparison | M37: SUPERSEDED: old Sample-E h*K=0.04 (use clasen_e_km@0.03)
A38: FALSE | B38: 37 | C38: C6 | D38: styext | E38: 11200 | F38: 0.04 | G38: fenepm | H38: constant | I38: 0.51 | J38: 1 | K38: clasen | L38: julia/experiments/tnwpaper/outputs/exptl_comparison | M38: SUPERSEDED: old Sample-E h*K=0.04 (use clasen_e_km@0.03)
A39: FALSE | B39: 38 | C39: C6 | D39: styext | E39: 11200 | F39: 0.04 | G39: fenepm | H39: c2d2 | I39: 0.51 | J39: 1 | K39: clasen | L39: julia/experiments/tnwpaper/outputs/exptl_comparison | M39: SUPERSEDED: old Sample-E h*K=0.04 (use clasen_e_km@0.03)
A40: FALSE | B40: 39 | C40: C6 | D40: caber | E40: 11200 | F40: 0.04 | G40: fenepm | H40: constant | I40: 0.51 | J40: [0.01, 0.03, 0.1, 0.3, 1, 3, 10, 30, 100] | K40: clasen | L40: julia/experiments/tnwpaper/outputs/exptl_comparison | M40: SUPERSEDED: old Sample-E h*K=0.04 (use clasen_e_km@0.03)
...

Sheet Gaillard_visc
A1: sample_id | B1: NK | C1: phi | D1: De | E1: Wie
A2: G1 | B2: 29197.08 | C2: 0.02 | D2: 8.904048 | E2: 0.7539513
A3: G1 | B3: 29197.08 | C3: 0.02 | D3: 10.844516 | E3: 0.82508577
A4: G1 | B4: 29197.08 | C4: 0.02 | D4: 13.200233 | E4: 0.9450603
A5: G1 | B5: 29197.08 | C5: 0.02 | D5: 15.651571 | E5: 1.0342812
A6: G1 | B6: 29197.08 | C6: 0.02 | D6: 18.539004 | E6: 1.1273868
A7: G1 | B7: 29197.08 | C7: 0.02 | D7: 18.639228 | E7: 1.6482705
A8: G1 | B8: 29197.08 | C8: 0.02 | D8: 22.200109 | E8: 1.8354785
A9: G1 | B9: 29197.08 | C9: 0.02 | D9: 24.093413 | E9: 1.3850429
A10: G1 | B10: 29197.08 | C10: 0.02 | D10: 29.807703 | E10: 2.1316048
A11: G1 | B11: 29197.08 | C11: 0.02 | D11: 30.224336 | E11: 2.0145654
A12: G1 | B12: 29197.08 | C12: 0.02 | D12: 35.844467 | E12: 2.2914357
A13: G1 | B13: 29197.08 | C13: 0.02 | D13: 39.02665 | E13: 1.7777909
... A22: G1 | B22: 29197.08 | C22: 0.02 | D22: 98.324147 | E22: 4.7936813

Sheet Gaillard_aq
A1: sample_id | B1: NK | C1: phi | D1: De | E1: Wie | G1: De col = De_0_v (viscous). NB low-Oh: De_0_v~300-700 (>>0.1-100 sweep); De_0_R(inertial)~1.5-4 in Gaillard_expdata col P. 10000ppm entangled (lam1 invalid).
A2: GA_5 | B2: =Gaillard_expdata!$C$42/137 | C2: =Gaillard_expdata!C50 | D2: =Gaillard_expdata!O50 | E2: =Gaillard_expdata!T50
A3: GA_10 | B3: =Gaillard_expdata!$C$42/137 | C3: =Gaillard_expdata!C51 | D3: =Gaillard_expdata!O51 | E3: =Gaillard_expdata!T51
A4: GA_25 | B4: =Gaillard_expdata!$C$42/137 | C4: =Gaillard_expdata!C52 | D4: =Gaillard_expdata!O52 | E4: =Gaillard_expdata!T52
A5: GA_50 | B5: =Gaillard_expdata!$C$42/137 | C5: =Gaillard_expdata!C53 | D5: =Gaillard_expdata!O53 | E5: =Gaillard_expdata!T53
A6: GA_100 | B6: =Gaillard_expdata!$C$42/137 | C6: =Gaillard_expdata!C54 | D6: =Gaillard_expdata!O54 | E6: =Gaillard_expdata!T54
A7: GA_250 | B7: =Gaillard_expdata!$C$42/137 | C7: =Gaillard_expdata!C55 | D7: =Gaillard_expdata!O55 | E7: =Gaillard_expdata!T55
A8: GA_500 | B8: =Gaillard_expdata!$C$42/137 | C8: =Gaillard_expdata!C56 | D8: =Gaillard_expdata!O56 | E8: =Gaillard_expdata!T56
A9: GA_1000 | B9: =Gaillard_expdata!$C$42/137 | C9: =Gaillard_expdata!C57 | D9: =Gaillard_expdata!O57 | E9: =Gaillard_expdata!T57
A10: GA_2500 | B10: =Gaillard_expdata!$C$42/137 | C10: =Gaillard_expdata!C58 | D10: =Gaillard_expdata!O58 | E10: =Gaillard_expdata!T58
A11: GA_10000 | B11: =Gaillard_expdata!$C$42/137 | C11: =Gaillard_expdata!C59 | D11: =Gaillard_expdata!O59 | E11: =Gaillard_expdata!T59

Sheet Anna
A1: sample_id | B1: NK | C1: phi | D1: De | E1: Wie
A2: A1 | B2: 2695.4178 | C2: 0.1260831 | D2: 5.2602678 | E2: 0.77324974
A3: A2 | B3: 8760.1078 | C3: 0.22729954 | D3: 50.697775 | E3: 0.74580336
A4: A3 | B4: 26954.178 | C4: 0.39870978 | D4: 261.09626 | E4: 0.67982456

Sheet Clasen
A1: sample_id | B1: NK | C1: phi | D1: De | E1: Wie
A2: C1 | B2: 11185.984 | C2: 0.0040582427 | D2: 6.643 | E2: 2.0701596
A3: C2 | B3: 11185.984 | C3: 0.0051370161 | D3: 6.654 | E3: 1.7226063
A4: C3 | B4: 11185.984 | C4: 0.016232971 | D4: 6.766 | E4: 0.84854182
A5: C4 | B5: 11185.984 | C5: 0.051370161 | D5: 7.131 | E5: 0.38399576
A6: C5 | B6: 11185.984 | C6: 0.16232971 | D6: 8.421 | E6: 0.14483534
A7: C6 | B7: 11185.984 | C7: 0.51370161 | D7: 14.254 | E7: 0.079168469

Sheet Calabrese
A1: sample_id | B1: NK | C1: phi | D1: De | E1: Wie
A2: VC1 | B2: 9258.7601 | C2: 0.089372085 | D2: 12.560501 | E2: 0.57024973
A3: VC1 | B3: 9258.7601 | C3: 0.089372085 | D3: 16.747334 | E3: 0.57024973
A4: VC1 | B4: 9258.7601 | C4: 0.089372085 | D4: 25.121001 | E4: 0.64153095
A5: VC2 | B5: 9258.7601 | C5: 0.22343021 | D5: 12.560501 | E5: 0.36658911
A6: VC2 | B6: 9258.7601 | C6: 0.22343021 | D6: 16.747334 | E6: 0.36658911
A7: VC2 | B7: 9258.7601 | C7: 0.22343021 | D7: 25.121001 | E7: 0.36658911
A8: VC3 | B8: 21785.714 | C8: 0.034272942 | D8: 45.335187 | E8: 0.78825765
A9: VC3 | B9: 21785.714 | C9: 0.034272942 | D9: 60.446916 | E9: 0.77183562
A10: VC3 | B10: 21785.714 | C10: 0.034272942 | D10: 90.670374 | E10: 0.82329133
A11: VC4 | B11: 21785.714 | C11: 0.068545884 | D11: 45.335187 | E11: 0.48114428
A12: VC4 | B12: 21785.714 | C12: 0.068545884 | D12: 60.446916 | E12: 0.47497577
A13: VC4 | B13: 21785.714 | C13: 0.068545884 | D13: 90.670374 | E13: 0.54482514

Sheet Gaillard_expdata
A1: Fig. 5 A
C2: PEO_visc
A3: Mw | C3: 4000000 | D3: From paper
A4: c (ppm = mg/kg) | C4: 25 | D4: From paper
A5: rho (kg/cu.m) | C5: 1048 | D5: From paper
A6: c (g/cu.m) | C6: =C4/1000*C5
A7: eta_p (Pa s) | C7: 0.0033 | D7: From paper
A8: lambda_eta (ms) | C8: =C7/(C6/C3*6.023E+23*1.380649E-23*298)*1000
A9: lambda_1 (ms) | C9: =C8/1.835 | D9: Uses U_eta lambda value from Kroeger et al, JCP, 2000
A10: eta_0 (Pa s) | C10: 0.248 | D10: From paper
A11: eta_s (Pas) | C11: =C10-C7
A12: sigma (N/m) | C12: 0.056
A13: c/c* | C13: 0.02 | D13: From paper - claculated using Graessley's estimate for polymers in good solvents
A14: NK | C14: =C3/137 | D14: MK = 137 from Hao-Yy et al. J. Rheol., 2025; Rubinstein & Colby
C15: h0 (mu-m) | D15: tau_e (ms) | E15: Oh0 | F15: De_v | G15: Wi_e | H15: h1 (mu-m) | I15: R_ve | J15: De_ve (visc)
B16: From Fig 2a | C16: 257.88022 | D16: 15.40862 | E16: =$C$11/($C$5*$C$12*C16*0.000001) | F16: =$C$9*0.001/($C$11*C16*0.000001/$C$12) | G16: =2/3*$C$9/D16 | H16: =$C$38*C16 | I16: =H16/C16 | J16: =F16/I16
B17: From Fig 2a | C17: 282.56528 | D17: 26.118109 | E17: =$C$11/($C$5*$C$12*C17*0.000001) | F17: =$C$9*0.001/($C$11*C17*0.000001/$C$12) | G17: =2/3*$C$9/D17 | H17: =$C$38*C17 | I17: =H17/C17 | J17: =F17/I17
B18: From Fig 2a | C18: 329.47986 | D18: 17.687658 | E18: =$C$11/($C$5*$C$12*C18*0.000001) | F18: =$C$9*0.001/($C$11*C18*0.000001/$C$12) | G18: =2/3*$C$9/D18 | H18: =$C$38*C18 | I18: =H18/C18 | J18: =F18/I18
B19: From Fig 2a | C19: 431.1312 | D19: 18.208508 | E19: =$C$11/($C$5*$C$12*C19*0.000001) | F19: =$C$9*0.001/($C$11*C19*0.000001/$C$12) | G19: =2/3*$C$9/D19 | H19: =$C$38*C19 | I19: =H19/C19 | J19: =F19/I19
B20: From Fig 2a | C20: 459.33105 | D20: 22.74727 | E20: =$C$11/($C$5*$C$12*C20*0.000001) | F20: =$C$9*0.001/($C$11*C20*0.000001/$C$12) | G20: =2/3*$C$9/D20 | H20: =$C$38*C20 | I20: =H20/C20 | J20: =F20/I20
B21: From Fig 2a | C21: 507.54565 | D21: 26.785614 | E21: =$C$11/($C$5*$C$12*C21*0.000001) | F21: =$C$9*0.001/($C$11*C21*0.000001/$C$12) | G21: =2/3*$C$9/D21 | H21: =$C$38*C21 | I21: =H21/C21 | J21: =F21/I21
B22: From Fig 2a | C22: 590.70447 | D22: 32.719 | E22: =$C$11/($C$5*$C$12*C22*0.000001) | F22: =$C$9*0.001/($C$11*C22*0.000001/$C$12) | G22: =2/3*$C$9/D22 | H22: =$C$38*C22 | I22: =H22/C22 | J22: =F22/I22
B23: From Fig 2a | C23: 707.3854 | D23: 32.234818 | E23: =$C$11/($C$5*$C$12*C23*0.000001) | F23: =$C$9*0.001/($C$11*C23*0.000001/$C$12) | G23: =2/3*$C$9/D23 | H23: =$C$38*C23 | I23: =H23/C23 | J23: =F23/I23
B24: From Fig 2a | C24: 838.92175 | D24: 36.664986 | E24: =$C$11/($C$5*$C$12*C24*0.000001) | F24: =$C$9*0.001/($C$11*C24*0.000001/$C$12) | G24: =2/3*$C$9/D24 | H24: =$C$38*C24 | I24: =H24/C24 | J24: =F24/I24
B25: From Fig 2a | C25: 850.64764 | D25: 34.651833 | E25: =$C$11/($C$5*$C$12*C25*0.000001) | F25: =$C$9*0.001/($C$11*C25*0.000001/$C$12) | G25: =2/3*$C$9/D25 | H25: =$C$38*C25 | I25: =H25/C25 | J25: =F25/I25
B26: From Fig 2a | C26: 1142.1499 | D26: 40.242374 | E26: =$C$11/($C$5*$C$12*C26*0.000001) | F26: =$C$9*0.001/($C$11*C26*0.000001/$C$12) | G26: =2/3*$C$9/D26 | H26: =$C$38*C26 | I26: =H26/C26 | J26: =F26/I26
B27: From Fig 2a | C27: 1360.3489 | D27: 44.81304 | E27: =$C$11/($C$5*$C$12*C27*0.000001) | F27: =$C$9*0.001/($C$11*C27*0.000001/$C$12) | G27: =2/3*$C$9/D27 | H27: =$C$38*C27 | I27: =H27/C27 | J27: =F27/I27
... B36: From Fig. 2b | C36: 2847.677 | D36: 97.96921 | E36: =$C$11/($C$5*$C$12*C36*0.000001) | F36: =$C$9*0.001/($C$11*C36*0.000001/$C$12) | G36: =2/3*$C$9/D36 | H36: =$C$38*C36 | I36: =H36/C36 | J36: =F36/I36
A38: R_ve (PEO_visc) from 2025 Fig 4b (~const) | C38: 0.063 | D38: 2025 Fig 4b squares, mean h1/h0
A40: PEO_aq (4M PEO in water, Gaillard 2025 conc. series; 2R0=3.5mm, h0~460um)
B42: Mw | C42: 4000000
B43: rho (kg/cu.m) | C43: 998
B44: eta_s (Pas) | C44: 0.00092 | D44: water
B45: h0 (um) | C45: 460 | D45: 2R0=3.5mm, V*~2.4
B46: T (K) | C46: 298
B47: U_eta (lam_eta/lam_1) | C47: 1.835 | D47: Kroeger 2000
B49: c (ppm) | C49: c/c* | D49: sigma (N/m) | E49: eta_p (Pas) | F49: lambda_eta (ms) | G49: lambda_1 (ms) | H49: tau_e (ms) | I49: h1 (um) | J49: h0 (um) | K49: R_ve | L49: Oh | M49: lambda_v (ms) | N49: lambda_R (ms) | O49: De_0_v | P49: De_0_R | Q49: De_ve_v | R49: De_ve_R | S49: edot (1/s) | T49: Wi_e
B50: 5 | C50: 0.019 | D50: 0.072 | E50: 1.3e-05 | F50: =E50/((B50/1000*$C$43)/$C$42*6.023E+23*1.380649E-23*$C$46)*1000 | G50: =F50/$C$47 | H50: 0.1 | I50: 21.6 | J50: =$C$45 | K50: =I50/J50 | L50: =$C$44/SQRT($C$43*D50*J50*0.000001) | M50: =$C$44*J50*0.000001/D50*1000 | N50: =SQRT($C$43*(J50*0.000001)^3/D50)*1000 | O50: =G50/M50 | P50: =G50/N50 | Q50: =O50/K50 | R50: =P50/K50^1.5 | S50: =2/(3*H50*0.001) | T50: =S50*G50*0.001
B51: 10 | C51: 0.037 | D51: 0.072 | E51: 2e-05 | F51: =E51/((B51/1000*$C$43)/$C$42*6.023E+23*1.380649E-23*$C$46)*1000 | G51: =F51/$C$47 | H51: 0.39 | I51: 31.3 | J51: =$C$45 | K51: =I51/J51 | L51: =$C$44/SQRT($C$43*D51*J51*0.000001) | M51: =$C$44*J51*0.000001/D51*1000 | N51: =SQRT($C$43*(J51*0.000001)^3/D51)*1000 | O51: =G51/M51 | P51: =G51/N51 | Q51: =O51/K51 | R51: =P51/K51^1.5 | S51: =2/(3*H51*0.001) | T51: =S51*G51*0.001
B52: 25 | C52: 0.093 | D52: 0.0634 | E52: 6.5e-05 | F52: =E52/((B52/1000*$C$43)/$C$42*6.023E+23*1.380649E-23*$C$46)*1000 | G52: =F52/$C$47 | H52: 1.4 | I52: 37.3 | J52: =$C$45 | K52: =I52/J52 | L52: =$C$44/SQRT($C$43*D52*J52*0.000001) | M52: =$C$44*J52*0.000001/D52*1000 | N52: =SQRT($C$43*(J52*0.000001)^3/D52)*1000 | O52: =G52/M52 | P52: =G52/N52 | Q52: =O52/K52 | R52: =P52/K52^1.5 | S52: =2/(3*H52*0.001) | T52: =S52*G52*0.001
...

Sheet Anna_expdata
A1: Fig. 5 B
A2: PS in Styrene oil
B3: 2M | C3: 6.5 M | D3: 20 M
A4: Mw | B4: 2000000 | C4: 6500000 | D4: 20000000 | E4: From paper
A5: NK | B5: =B4/742 | C5: =C4/742 | D5: =D4/742
A6: c (w% = g/100 g) | B6: 0.05 | C6: 0.05 | D6: 0.05 | E6: From paper
A7: rho (kg/cu.m) | B7: 1026 | C7: 1026 | D7: 1026 | E7: From paper
A8: c (g/cu.m) | B8: =B6/100*B7*1000 | C8: =C6/100*C7*1000 | D8: =D6/100*D7*1000
A9: c/c* | B9: =B8/B4*6.023E+23*(0.0000000018*B5^0.5)^3 | C9: =C8/C4*6.023E+23*(0.0000000018*C5^0.5)^3 | D9: =D8/D4*6.023E+23*(0.0000000018*D5^0.5)^3 | E9: number density * E0^3
A10: eta_s (Pas) | B10: 34 | C10: 34 | D10: 34 | E10: From paper
A11: sigma (N/m) | B11: 0.0378 | C11: 0.0378 | D11: 0.0378 | E11: From paper
A12: eta_0 (Pa s) | B12: 39.2 | C12: 46.1 | D12: 55.5 | E12: From paper
A13: eta_p (Pa s) | B13: =B12-B10 | C13: =C12-C10 | D13: =D12-D10
A14: lambda_eta (s) | B14: =B13/(B8/B4*6.023E+23*1.381E-23*294) | C14: =C13/(C8/C4*6.023E+23*1.381E-23*294) | D14: =D13/(D8/D4*6.023E+23*1.381E-23*294)
A15: lambda_1 (s) | B15: 3.7 | C15: 31.1 | D15: 155 | E15: From paper
A16: R0 (mm) | B16: =1.564/2 | C16: =1.364/2 | D16: =1.32/2 | E16: From paper
A17: lambda_v (s) | B17: =B10*B16/B11/1000 | C17: =C10*C16/C11/1000 | D17: =D10*D16/D11/1000
A18: De_v | B18: =B15/B17 | C18: =C15/C17 | D18: =D15/D17
A19: lambda_eta/lambda_1 | B19: =B14/B15 | C19: =C14/C15 | D19: =D14/D15
A20: lambda_e(s) | B20: 3.19 | C20: 27.8 | D20: 152 | E20: From paper
A21: strain rate (1/s) | B21: =2/(3*B20) | C21: =2/(3*C20) | D21: =2/(3*D20)
A22: Wi_e | B22: =B21*B15 | C22: =C21*C15 | D22: =D21*D15
A23: [eta] ml/g | B23: 70.2 | C23: 136 | D23: 255
A24: c/c*_KM | B24: =B8/1000000*B23*5*EXP(1) | C24: =C8/1000000*C23*5*EXP(1) | D24: =D8/1000000*D23*5*EXP(1)
A25: R_ve (D_ve/D_1, Fig 4 ~const) | B25: 0.65 | C25: 0.65 | D25: 0.65 | E25: D_ve/D_1 from Fig 4
A26: h1 (mm) | B26: =B16*B25 | C26: =C16*C25 | D26: =D16*D25
A27: De_ve | B27: =B18/B25 | C27: =C18/C25 | D27: =D18/D25

Sheet Clasen_expdata
B1: Remarks | AF1: Remarks
A2: PS in OS | AE2: PS in DEP
A3: Sample ID | B3: From Clasen-data: Boger A | C3: E | D3: E | E3: E | F3: E | G3: E | H3: E | I3: C | J3: C | K3: C | L3: C | M3: C | N3: B | O3: B | P3: B | Q3: B | R3: B | S3: B | T3: B | U3: A | V3: A | W3: A | X3: A | Y3: A | Z3: D | AA3: D | AB3: D | AC3: D | AD3: D | AE3: Sample ID | AF3: From Clasen-data: DEP A | AG3: X | AH3: X | AI3: X | AJ3: X | AK3: Y | AL3: Y | AM3: Y | AN3: Y
A4: Mw | B4: From Clasen-data: Boger M | C4: 8300000 | D4: 8300000 | E4: 8300000 | F4: 8300000 | G4: 8300000 | H4: 8300000 | I4: 5700000 | J4: 5700000 | K4: 5700000 | L4: 5700000 | M4: 5700000 | N4: 2800000 | O4: 2800000 | P4: 2800000 | Q4: 2800000 | R4: 2800000 | S4: 2800000 | T4: 2800000 | U4: 1800000 | V4: 1800000 | W4: 1800000 | X4: 1800000 | Y4: 1800000 | Z4: 6000000 | AA4: 6000000 | AB4: 6000000 | AC4: 6000000 | AD4: 6000000 | AE4: Mw | AF4: From Clasen-data: DEP M | AG4: 8300000 | AH4: 8300000 | AI4: 8300000 | AJ4: 8300000 | AK4: 5700000 | AL4: 5700000 | AM4: 5700000 | AN4: 5700000
A5: NK | B5: Calculated | C5: =C4/742 | D5: =D4/742 | E5: =E4/742 | F5: =F4/742 | G5: =G4/742 | H5: =H4/742 | I5: =I4/742 | J5: =J4/742 | ... AD5: =AD4/742 | AE5: NK | AF5: Calculated | AG5: =AG4/742 | AH5: =AH4/742 | AI5: =AI4/742 | AJ5: =AJ4/742 | AK5: =AK4/742 | AL5: =AL4/742 | AM5: =AM4/742 | AN5: =AN4/742
A6: c (g/g) | B6: From Clasen-data: Boger AE | C6: 7.9e-06 | D6: 1e-05 | E6: 3.16e-05 | F6: 0.0001 | G6: 0.000316 | H6: 0.001 | I6: 7.9e-06 | J6: 1e-05 | K6: 3.16e-05 | L6: 0.0001 | M6: 0.000316 | N6: 4.4e-06 | O6: 7.5e-06 | P6: 1.4e-05 | Q6: 2.5e-05 | R6: 4.4e-05 | S6: 7.9e-05 | T6: 0.000144 | U6: 1e-05 | V6: 5e-05 | W6: 0.0001 | X6: 0.00025 | Y6: 0.0005 | Z6: 1e-05 | AA6: 5e-05 | AB6: 0.0001 | AC6: 0.00025 | AD6: 0.00075 | AE6: c (g/g) | AF6: From Clasen-data: DEP AE | AG6: 0.0001 | AH6: 0.000316 | AI6: 0.001 | AJ6: 0.00316 | AK6: 0.0001 | AL6: 0.000316 | AM6: 0.001 | AN6: 0.00316
A7: rho (kg/cu.m) | B7: From Clasen-data: Boger X | C7: 1026 | D7: 1026 | E7: 1026 | F7: 1026 | G7: 1026 | H7: 1026 | I7: 1026 | J7: 1026 | K7: 1026 | L7: 1026 | M7: 1026 | N7: 1026 | O7: 1026 | P7: 1026 | Q7: 1026 | R7: 1026 | S7: 1026 | T7: 1026 | U7: 1026 | V7: 1026 | W7: 1026 | X7: 1026 | Y7: 1026 | Z7: 1026 | AA7: 1026 | AB7: 1026 | AC7: 1026 | AD7: 1026 | AE7: rho (kg/cu.m) | AF7: From Clasen-data:DEP X | AG7: 1118 | AH7: 1118 | AI7: 1118 | AJ7: 1118 | AK7: 1118 | AL7: 1118 | AM7: 1118 | AN7: 1118
A8: c (g/cu.m) | B8: Calculated | C8: =C6*C7*1000 | D8: =D6*D7*1000 | E8: =E6*E7*1000 | F8: =F6*F7*1000 | G8: =G6*G7*1000 | H8: =H6*H7*1000 | I8: =I6*I7*1000 | J8: =J6*J7*1000 | ... AD8: =AD6*AD7*1000 | AE8: c (g/cu.m) | AF8: Calculated | AG8: =AG6*AG7*1000 | AH8: =AH6*AH7*1000 | AI8: =AI6*AI7*1000 | AJ8: =AJ6*AJ7*1000 | AK8: =AK6*AK7*1000 | AL8: =AL6*AL7*1000 | AM8: =AM6*AM7*1000 | AN8: =AN6*AN7*1000
A9: c/c* | B9: Calculated | C9: =C8/C4*6.023E+23*(0.0000000018*C5^0.5)^3 | D9: =D8/D4*6.023E+23*(0.0000000018*D5^0.5)^3 | E9: =E8/E4*6.023E+23*(0.0000000018*E5^0.5)^3 | F9: =F8/F4*6.023E+23*(0.0000000018*F5^0.5)^3 | G9: =G8/G4*6.023E+23*(0.0000000018*G5^0.5)^3 | H9: =H8/H4*6.023E+23*(0.0000000018*H5^0.5)^3 | I9: =I8/I4*6.023E+23*(0.0000000018*I5^0.5)^3 | J9: =J8/J4*6.023E+23*(0.0000000018*J5^0.5)^3 | ... AD9: =AD8/AD4*6.023E+23*(0.0000000018*AD5^0.5)^3 | AE9: c/c* | AF9: Calculated | AG9: =AG8/AG4*6.023E+23*(0.0000000018*AG5^0.5)^3 | AH9: =AH8/AH4*6.023E+23*(0.0000000018*AH5^0.5)^3 | AI9: =AI8/AI4*6.023E+23*(0.0000000018*AI5^0.5)^3 | AJ9: =AJ8/AJ4*6.023E+23*(0.0000000018*AJ5^0.5)^3 | AK9: =AK8/AK4*6.023E+23*(0.0000000018*AK5^0.5)^3 | AL9: =AL8/AL4*6.023E+23*(0.0000000018*AL5^0.5)^3 | AM9: =AM8/AM4*6.023E+23*(0.0000000018*AM5^0.5)^3 | AN9: =AN8/AN4*6.023E+23*(0.0000000018*AN5^0.5)^3
A10: eta_s (Pas) | B10: From Clasen-data: Boger P | C10: 40 | D10: 40 | E10: 40 | F10: 40 | G10: 40 | H10: 40 | I10: 40 | J10: 40 | K10: 40 | L10: 40 | M10: 40 | N10: 51 | O10: 51 | P10: 51 | Q10: 51 | R10: 51 | S10: 51 | T10: 51 | U10: 33 | V10: 33 | W10: 33 | X10: 33 | Y10: 33 | Z10: 33 | AA10: 33 | AB10: 33 | AC10: 33 | AD10: 33 | AE10: eta_s (Pas) | AF10: From Clasen-data: DEP P | AG10: 0.011 | AH10: 0.011 | AI10: 0.011 | AJ10: 0.011 | AK10: 0.011 | AL10: 0.011 | AM10: 0.011 | AN10: 0.011
A11: sigma (N/m) | B11: From Clasen-data: Boger Q | C11: 0.0378 | D11: 0.0378 | E11: 0.0378 | F11: 0.0378 | G11: 0.0378 | H11: 0.0378 | I11: 0.0378 | J11: 0.0378 | K11: 0.0378 | L11: 0.0378 | M11: 0.0378 | N11: 0.0378 | O11: 0.0378 | P11: 0.0378 | Q11: 0.0378 | R11: 0.0378 | S11: 0.0378 | T11: 0.0378 | U11: 0.0378 | V11: 0.0378 | W11: 0.0378 | X11: 0.0378 | Y11: 0.0378 | Z11: 0.0378 | AA11: 0.0378 | AB11: 0.0378 | AC11: 0.0378 | AD11: 0.0378 | AE11: sigma (N/m) | AF11: From Clasen-data: DEP Q | AG11: 0.0375 | AH11: 0.0375 | AI11: 0.0375 | AJ11: 0.0375 | AK11: 0.0375 | AL11: 0.0375 | AM11: 0.0375 | AN11: 0.0375
A12: eta_0 (Pa s) | B12: Ignore | AE12: eta_0 (Pa s) | AF12: Ignore
A13: eta_p (Pa s) | B13: Ignore | AE13: eta_p (Pa s) | AF13: Ignore
A14: lambda_eta (s) | B14: Ignore | AE14: lambda_eta (s) | AF14: Ignore
A15: lambda_1 /lambda_Z | B15: From Clasen-data: Boger AL | C15: 1.0060976 | D15: 1.0077247 | E15: 1.0246142 | F15: 1.0799881 | G15: 1.2752752 | H15: 2.1586866 | I15: 1.0049199 | J15: 1.0062318 | K15: 1.0198252 | L15: 1.0640946 | M15: 1.2169075 | N15: 1.0018571 | O15: 1.0031677 | P15: 1.0059211 | Q15: 1.0105979 | R15: 1.0187274 | S15: 1.0338743 | T15: 1.0626043 | U15: 1.0032732 | V15: 1.0164733 | W15: 1.0332179 | X15: 1.0851251 | Y15: 1.1774964 | Z15: 1.0064331 | AA15: 1.032582 | AB15: 1.0662257 | AC15: 1.1738777 | AD15: 1.6175902 | AE15: lambda_1 /lambda_Z | AF15: From Clasen-data: DEP AL | AG15: 1.0237958 | AH15: 1.0771451 | AI15: 1.2651255 | AJ15: 2.1025298 | AK15: 1.0183221 | AL15: 1.0590518 | AM15: 1.1990903 | AN15: 1.7748922
A16: R0 (mm) | B16: From Clasen-data: Boger S | C16: 1.195 | D16: 1.195 | E16: 1.195 | F16: 1.195 | G16: 1.195 | H16: 1.195 | I16: 1.195 | J16: 1.195 | K16: 1.195 | L16: 1.195 | M16: 1.195 | N16: 1.195 | O16: 1.195 | P16: 1.195 | Q16: 1.195 | R16: 1.195 | S16: 1.195 | T16: 1.195 | U16: 0.5975 | V16: 0.5975 | W16: 0.5975 | X16: 0.5975 | Y16: 0.5975 | Z16: 0.5975 | AA16: 0.5975 | AB16: 0.5975 | AC16: 0.5975 | AD16: 0.5975 | AE16: R0 (mm) | AF16: From Clasen-data: DEP S | AG16: 1.195 | AH16: 1.195 | AI16: 1.195 | AJ16: 1.195 | AK16: 1.195 | AL16: 1.195 | AM16: 1.195 | AN16: 1.195
A17: lambda_v (s) | B17: Calculated | C17: =C10*C16/C11/1000 | D17: =D10*D16/D11/1000 | E17: =E10*E16/E11/1000 | F17: =F10*F16/F11/1000 | G17: =G10*G16/G11/1000 | H17: =H10*H16/H11/1000 | I17: =I10*I16/I11/1000 | J17: =J10*J16/J11/1000 | ... AD17: =AD10*AD16/AD11/1000 | AE17: lambda_v (s) | AF17: Calculated | AG17: =AG10*AG16/AG11/1000 | AH17: =AH10*AH16/AH11/1000 | AI17: =AI10*AI16/AI11/1000 | AJ17: =AJ10*AJ16/AJ11/1000 | AK17: =AK10*AK16/AK11/1000 | AL17: =AL10*AL16/AL11/1000 | AM17: =AM10*AM16/AM11/1000 | AN17: =AN10*AN16/AN11/1000
A18: De_v | B18: Calculated | C18: =C15*C28/C17 | D18: =D15*D28/D17 | E18: =E15*E28/E17 | F18: =F15*F28/F17 | G18: =G15*G28/G17 | H18: =H15*H28/H17 | I18: =I15*I28/I17 | J18: =J15*J28/J17 | ... AD18: =AD15*AD28/AD17 | AE18: De_v | AF18: Calculated | AG18: =AG15*AG28/AG17 | AH18: =AH15*AH28/AH17 | AI18: =AI15*AI28/AI17 | AJ18: =AJ15*AJ28/AJ17 | AK18: =AK15*AK28/AK17 | AL18: =AL15*AL28/AL17 | AM18: =AM15*AM28/AM17 | AN18: =AN15*AN28/AN17
A19: lambda_eta/lambda_1 | B19: Ignore | AE19: lambda_eta/lambda_1 | AF19: Ignore
A20: lambda_e/lambda_Z | B20: From Clasen-data: Boger AK | C20: 0.324 | D20: 0.39 | E20: 0.805 | F20: 1.875 | G20: 5.87 | H20: 18.178 | I20: 0.486 | J20: 0.523 | K20: 0.733 | L20: 1.277 | M20: 5.69 | N20: 0.354 | O20: 0.629 | P20: 0.702 | Q20: 0.99 | R20: 1.121 | S20: 1.876 | T20: 2.033 | U20: 0.548 | V20: 0.995 | W20: 1.286 | X20: 2.699 | Y20: 5.019 | Z20: 0.392 | AA20: 0.683 | AB20: 1.482 | AC20: 4.034 | AD20: 8.312 | AE20: lambda_e/lambda_Z | AF20: From Clasen-data: DEP AK | AG20: 1.12 | AH20: 1.819 | AI20: 2.784 | AJ20: 6.753 | AK20: 0.81 | AL20: 1.11 | AM20: 2.303 | AN20: 4.102
A21: strain rate (1/s) | B21: Ignore | AE21: strain rate (1/s) | AF21: Ignore
A22: Wi_e | B22: Calculated | C22: =(2/3)*C15/C20 | D22: =(2/3)*D15/D20 | E22: =(2/3)*E15/E20 | F22: =(2/3)*F15/F20 | G22: =(2/3)*G15/G20 | H22: =(2/3)*H15/H20 | I22: =(2/3)*I15/I20 | J22: =(2/3)*J15/J20 | ... AD22: =(2/3)*AD15/AD20 | AE22: Wi_e | AF22: Calculated | AG22: =(2/3)*AG15/AG20 | AH22: =(2/3)*AH15/AH20 | AI22: =(2/3)*AI15/AI20 | AJ22: =(2/3)*AJ15/AJ20 | AK22: =(2/3)*AK15/AK20 | AL22: =(2/3)*AL15/AL20 | AM22: =(2/3)*AM15/AM20 | AN22: =(2/3)*AN15/AN20
A23: L0 (mm) | B23: Ignore | C23: =0.5*3 | D23: =0.5*3 | E23: =0.5*3 | F23: =0.5*3 | G23: =0.5*3 | H23: =0.5*3 | AE23: L0 (mm) | AF23: Ignore
A24: P (mm) | B24: Ignore | C24: 1.5 | D24: 1.5 | E24: 1.5 | F24: 1.5 | G24: 1.5 | H24: 1.5 | AE24: P (mm) | AF24: Ignore
A25: V0 (mm)^3 | B25: Ignore | C25: =C23*PI()*C24^2 | D25: =D23*PI()*D24^2 | E25: =E23*PI()*E24^2 | F25: =F23*PI()*F24^2 | G25: =G23*PI()*G24^2 | H25: =H23*PI()*H24^2 | AE25: V0 (mm)^3 | AF25: Ignore
A26: LF(mm) | B26: Ignore | C26: =1.3*3 | D26: =1.3*3 | E26: =1.3*3 | F26: =1.3*3 | G26: =1.3*3 | H26: =1.3*3 | AE26: LF(mm) | AF26: Ignore
A27: Phi | B27: Ignore | C27: =C25/(PI()*C24^2*C26) | D27: =D25/(PI()*D24^2*D26) | E27: =E25/(PI()*E24^2*E26) | F27: =F25/(PI()*F24^2*F26) | G27: =G25/(PI()*G24^2*G26) | H27: =H25/(PI()*H24^2*H26) | AE27: Phi | AF27: Ignore
A28: lambda_Z | B28: From Clasen-data: Boger O | C28: 8.35 | D28: 8.35 | E28: 8.35 | F28: 8.35 | G28: 8.35 | H28: 8.35 | I28: 4.64 | J28: 4.64 | K28: 4.64 | L28: 4.64 | M28: 4.64 | N28: 2.01 | O28: 2.01 | P28: 2.01 | Q28: 2.01 | R28: 2.01 | S28: 2.01 | T28: 2.01 | U28: 0.64 | V28: 0.64 | W28: 0.64 | X28: 0.64 | Y28: 0.64 | Z28: 4.18 | AA28: 4.18 | AB28: 4.18 | AC28: 4.18 | AD28: 4.18 | AE28: lambda_Z | AF28: From Clasen-data: DEP O | AG28: 0.01017 | AH28: 0.01017 | AI28: 0.01017 | AJ28: 0.01017 | AK28: 0.0057 | AL28: 0.0057 | AM28: 0.0057 | AN28: 0.0057
A29: [eta]_0 | B29: From Clasen-data: Boger AG | C29: 150 | D29: 150 | E29: 150 | F29: 150 | G29: 150 | H29: 150 | I29: 121.1 | J29: 121.1 | K29: 121.1 | L29: 121.1 | M29: 121.1 | N29: 82.2 | O29: 82.2 | P29: 82.2 | Q29: 82.2 | R29: 82.2 | S29: 82.2 | T29: 82.2 | U29: 63.7 | V29: 63.7 | W29: 63.7 | X29: 63.7 | Y29: 63.7 | Z29: 125 | AA29: 125 | AB29: 125 | AC29: 125 | AD29: 125 | AE29: [eta]_0 | AF29: From Clasen-data: DEP AG | AG29: 601 | AH29: 601 | AI29: 601 | AJ29: 601 | AK29: 464 | AL29: 464 | AM29: 464 | AN29: 464
A30: KM | B30: From Clasen-data: Boger AI | C30: 5 | D30: 5 | E30: 5 | F30: 5 | G30: 5 | H30: 5 | I30: 5 | J30: 5 | K30: 5 | L30: 5 | M30: 5 | N30: 5 | O30: 5 | P30: 5 | Q30: 5 | R30: 5 | S30: 5 | T30: 5 | U30: 5 | V30: 5 | W30: 5 | X30: 5 | Y30: 5 | Z30: 5 | AA30: 5 | AB30: 5 | AC30: 5 | AD30: 5 | AE30: KM | AF30: From Clasen-data: DEP AI | AG30: 0.35 | AH30: 0.35 | AI30: 0.35 | AJ30: 0.35 | AK30: 0.35 | AL30: 0.35 | AM30: 0.35 | AN30: 0.35
A31: c/c*_KM | B31: Calculated | C31: =C8/1000000*C29*C30*EXP(1) | D31: =D8/1000000*D29*D30*EXP(1) | E31: =E8/1000000*E29*E30*EXP(1) | F31: =F8/1000000*F29*F30*EXP(1) | G31: =G8/1000000*G29*G30*EXP(1) | H31: =H8/1000000*H29*H30*EXP(1) | I31: =I8/1000000*I29*I30*EXP(1) | J31: =J8/1000000*J29*J30*EXP(1) | ... AD31: =AD8/1000000*AD29*AD30*EXP(1) | AE31: c/c*_KM | AF31: Calculated | AG31: =AG8/1000000*AG29*AG30*EXP(1) | AH31: =AH8/1000000*AH29*AH30*EXP(1) | AI31: =AI8/1000000*AI29*AI30*EXP(1) | AJ31: =AJ8/1000000*AJ29*AJ30*EXP(1) | AK31: =AK8/1000000*AK29*AK30*EXP(1) | AL31: =AL8/1000000*AL29*AL30*EXP(1) | AM31: =AM8/1000000*AM29*AM30*EXP(1) | AN31: =AN8/1000000*AN29*AN30*EXP(1)
A32: R_ve (D_ve/D0, Fig 10 ~const) | B32: From Clasen-data: Boger U | C32: 0.4 | D32: 0.4 | E32: 0.4 | F32: 0.4 | G32: 0.4 | H32: 0.4 | I32: 0.3 | J32: 0.3 | K32: 0.3 | L32: 0.3 | M32: 0.3 | N32: 0.3 | O32: 0.3 | P32: 0.3 | Q32: 0.3 | R32: 0.3 | S32: 0.3 | T32: 0.3 | U32: 0.3 | V32: 0.3 | W32: 0.3 | X32: 0.3 | Y32: 0.3 | Z32: 0.3 | AA32: 0.3 | AB32: 0.3 | AC32: 0.3 | AD32: 0.3 | AE32: R_ve (D_ve/D0, Fig 10 ~const) | AF32: From Clasen-data: DEP U | AG32: 0.4 | AH32: 0.4 | AI32: 0.4 | AJ32: 0.4 | AK32: 0.4 | AL32: 0.4 | AM32: 0.4 | AN32: 0.4
A33: h1 (mm) | B33: Calculated | C33: =C16*C32 | D33: =D16*D32 | E33: =E16*E32 | F33: =F16*F32 | G33: =G16*G32 | H33: =H16*H32 | I33: =I16*I32 | J33: =J16*J32 | ... AD33: =AD16*AD32 | AE33: h1 (mm) | AF33: Calculated | AG33: =AG16*AG32 | AH33: =AH16*AH32 | AI33: =AI16*AI32 | AJ33: =AJ16*AJ32 | AK33: =AK16*AK32 | AL33: =AL16*AL32 | AM33: =AM16*AM32 | AN33: =AN16*AN32
A34: De_ve | B34: Calculated | C34: =C18/C32 | D34: =D18/D32 | E34: =E18/E32 | F34: =F18/F32 | G34: =G18/G32 | H34: =H18/H32 | I34: =I18/I32 | J34: =J18/J32 | ... AD34: =AD18/AD32 | AE34: De_ve | AF34: Calculated | AG34: =AG18/AG32 | AH34: =AH18/AH32 | AI34: =AI18/AI32 | AJ34: =AJ18/AJ32 | AK34: =AK18/AK32 | AL34: =AL18/AL32 | AM34: =AM18/AM32 | AN34: =AN18/AN32

Sheet Calabrese_expdata
A1: PS in DOP
B2: 7M | H2: 16M
A3: Mw | B3: 6870000 | C3: 6870000 | D3: 6870000 | E3: 6870000 | F3: 6870000 | G3: 6870000 | H3: 16165000 | I3: 16165000 | J3: 16165000 | K3: 16165000 | L3: 16165000 | M3: 16165000
A4: NK | B4: =B3/742 | C4: =C3/742 | D4: =D3/742 | E4: =E3/742 | F4: =F3/742 | G4: =G3/742 | H4: =H3/742 | I4: =I3/742 | ... M4: =M3/742
A5: c (w% = g/100 g) | B5: =200/1000000*100 | C5: =200/1000000*100 | D5: =200/1000000*100 | E5: =500/1000000*100 | F5: =500/1000000*100 | G5: =500/1000000*100 | H5: =50/1000000*100 | I5: =50/1000000*100 | J5: =50/1000000*100 | K5: =100/1000000*100 | L5: =100/1000000*100 | M5: =100/1000000*100
A6: rho (kg/cu.m) | B6: 981 | C6: 981 | D6: 981 | E6: 981 | F6: 981 | G6: 981 | H6: 981 | I6: 981 | J6: 981 | K6: 981 | L6: 981 | M6: 981
A7: c (g/cu.m) | B7: =B5/100*B6*1000 | C7: =C5/100*C6*1000 | D7: =D5/100*D6*1000 | E7: =E5/100*E6*1000 | F7: =F5/100*F6*1000 | G7: =G5/100*G6*1000 | H7: =H5/100*H6*1000 | I7: =I5/100*I6*1000 | ... M7: =M5/100*M6*1000
A8: c/c* | B8: =B7/B3*6.023E+23*(0.0000000018*B4^0.5)^3 | C8: =C7/C3*6.023E+23*(0.0000000018*C4^0.5)^3 | D8: =D7/D3*6.023E+23*(0.0000000018*D4^0.5)^3 | E8: =E7/E3*6.023E+23*(0.0000000018*E4^0.5)^3 | F8: =F7/F3*6.023E+23*(0.0000000018*F4^0.5)^3 | G8: =G7/G3*6.023E+23*(0.0000000018*G4^0.5)^3 | H8: =H7/H3*6.023E+23*(0.0000000018*H4^0.5)^3 | I8: =I7/I3*6.023E+23*(0.0000000018*I4^0.5)^3 | ... M8: =M7/M3*6.023E+23*(0.0000000018*M4^0.5)^3
A9: eta_s (Pas) | B9: 0.057 | C9: 0.057 | D9: 0.057 | E9: 0.057 | F9: 0.057 | G9: 0.057 | H9: 0.057 | I9: 0.057 | J9: 0.057 | K9: 0.057 | L9: 0.057 | M9: 0.057
A10: sigma (N/m) | B10: 0.031 | C10: 0.031 | D10: 0.031 | E10: 0.031 | F10: 0.031 | G10: 0.031 | H10: 0.031 | I10: 0.031 | J10: 0.031 | K10: 0.031 | L10: 0.031 | M10: 0.031
A11: eta_0 (Pa s) | B11: 0.059 | C11: 0.059 | D11: 0.059 | E11: 0.062 | F11: 0.062 | G11: 0.062
A12: eta_p (Pa s) | B12: =B11-B9 | C12: =C11-C9 | D12: =D11-D9 | E12: =E11-E9 | F12: =F11-F9 | G12: =G11-G9
A13: lambda_eta (s) | B13: =B12/(B7/B3*6.023E+23*1.381E-23*298) | C13: =C12/(C7/C3*6.023E+23*1.381E-23*298) | D13: =D12/(D7/D3*6.023E+23*1.381E-23*298) | E13: =E12/(E7/E3*6.023E+23*1.381E-23*298) | F13: =F12/(F7/F3*6.023E+23*1.381E-23*298) | G13: =G12/(G7/G3*6.023E+23*1.381E-23*298) | H13: =$E13*(H3/$E3)^1.5 | I13: =$E13*(I3/$E3)^1.5 | J13: =$E13*(J3/$E3)^1.5 | K13: =$E13*(K3/$E3)^1.5 | L13: =$E13*(L3/$E3)^1.5 | M13: =$E13*(M3/$E3)^1.5
A14: lambda_1 (s) | B14: =B13/1.835 | C14: =C13/1.835 | D14: =D13/1.835 | E14: =E13/1.835 | F14: =F13/1.835 | G14: =G13/1.835 | H14: =H13/1.835 | I14: =I13/1.835 | ... M14: =M13/1.835
A15: R0 (mm) | B15: =C15/3*2 | C15: 0.5 | D15: =C15/3*4 | E15: =F15/3*2 | F15: 0.5 | G15: =F15/3*4 | H15: =I15/3*2 | I15: 0.5 | J15: =I15/3*4 | K15: =L15/3*2 | L15: 0.5 | M15: =L15/3*4
A16: lambda_v (s) | B16: =B9*B15/B10/1000 | C16: =C9*C15/C10/1000 | D16: =D9*D15/D10/1000 | E16: =E9*E15/E10/1000 | F16: =F9*F15/F10/1000 | G16: =G9*G15/G10/1000 | H16: =H9*H15/H10/1000 | I16: =I9*I15/I10/1000 | ... M16: =M9*M15/M10/1000
A17: De_v | B17: =B14/B16 | C17: =C14/C16 | D17: =D14/D16 | E17: =E14/E16 | F17: =F14/F16 | G17: =G14/G16 | H17: =H14/H16 | I17: =I14/I16 | ... M17: =M14/M16
A18: lambda_eta/lambda_1 | B18: =B13/B14 | C18: =C13/C14 | D18: =D13/D14 | E18: =E13/E14 | F18: =F13/F14 | G18: =G13/G14 | H18: =H13/H14 | I18: =I13/I14 | ... M18: =M13/M14
A19: lambda_e(s) | B19: 0.016 | C19: 0.018 | D19: 0.018 | E19: 0.028 | F19: 0.028 | G19: 0.028 | H19: 0.045 | I19: 0.048 | J19: 0.047 | K19: 0.068 | L19: 0.078 | M19: 0.077
A20: strain rate (1/s) | B20: =2/(3*B19) | C20: =2/(3*C19) | D20: =2/(3*D19) | E20: =2/(3*E19) | F20: =2/(3*F19) | G20: =2/(3*G19) | H20: =2/(3*H19) | I20: =2/(3*I19) | ... M20: =2/(3*M19)
A21: Wi_e | B21: =B20*B14 | C21: =C20*C14 | D21: =D20*D14 | E21: =E20*E14 | F21: =F20*F14 | G21: =G20*G14 | H21: =H20*H14 | I21: =I20*I14 | ... M21: =M20*M14
A22: R_ve (Fig S2 ~0.6) | B22: 0.6 | C22: 0.6 | D22: 0.6 | E22: 0.6 | F22: 0.6 | G22: 0.6 | H22: 0.6 | I22: 0.6 | J22: 0.6 | K22: 0.6 | L22: 0.6 | M22: 0.6
A23: h1 (mm) | B23: =B15*B22 | C23: =C15*C22 | D23: =D15*D22 | E23: =E15*E22 | F23: =F15*F22 | G23: =G15*G22 | H23: =H15*H22 | I23: =I15*I22 | ... M23: =M15*M22
A24: De_ve (visc) | B24: =B17/B22 | C24: =C17/C22 | D24: =D17/D22 | E24: =E17/E22 | F24: =F17/F22 | G24: =G17/G22 | H24: =H17/H22 | I24: =I17/I22 | ... M24: =M17/M22

Sheet Gaillard_sandbox
A1: Experimental
B2: PEO_aq | E2: PEO_visc | M2: PEO_visc
A3: Mw | B3: 4000000 | E3: 4000000 | L3: Mw | M3: 4000000
A4: c (ppm = mg/kg) | B4: 500 | E4: 25 | L4: c (ppm = mg/kg) | M4: 25
A5: rho (kg/cu.m) | B5: 998 | E5: 1048 | L5: rho (kg/cu.m) | M5: 1048
A6: c (g/cu.m) | B6: =B4/1000*B5 | E6: =E4/1000*E5 | L6: c (g/cu.m) | M6: =M4/1000*M5
A7: eta_p (Pa s) | B7: 0.00208 | E7: 0.0033 | L7: eta_p (Pa s) | M7: 0.0033
A8: lambda_eta (ms) | B8: =B7/(B6/B3*6.023E+23*1.380649E-23*298)*1000 | E8: =E7/(E6/E3*6.023E+23*1.380649E-23*298)*1000 | L8: lambda_eta (ms) | M8: =M7/(M6/M3*6.023E+23*1.380649E-23*298)*1000
A9: lambda_1 (ms) | B9: =B13/1.835 | E9: =E8/1.835 | L9: lambda_1 (ms) | M9: =M8/1.835
A10: eta_0 (Pa s) | B10: 0.003 | E10: 0.248 | L10: eta_0 (Pa s) | M10: 0.248
A11: eta_s (Pas) | B11: =B10-B7 | E11: =E10-E7 | L11: eta_s (Pas) | M11: =M10-M7
A12: sigma (N/m) | B12: =62.5/1000 | E12: 0.056 | L12: sigma (N/m) | M12: 0.056
A13: c/c* | E13: 0.02 | H13: Factor | L13: c/c* | M13: 0.02
A14: NK | E14: =E3/137 | H14: 1 | I14: 1 | L14: NK | M14: =M3/137
B15: h0 (mu-m) | C15: tau_e (ms) | E15: h0 (mu-m) | F15: tau_e (ms) | G15: Oh0 | H15: De_v | I15: Wi_e
B16: 245.19879 | C16: 12.131915 | E16: 257.88022 | F16: 15.40862 | G16: =$E$11/($E$5*$E$12*E16*0.000001) | H16: =$E$9*0.001/($E$11*E16*0.000001/$E$12)*$H$14 | I16: =$E$9/F16*$I$14
B17: 277.31714 | C17: 15.663775 | E17: 282.56528 | F17: 26.118109 | G17: =$E$11/($E$5*$E$12*E17*0.000001) | H17: =$E$9*0.001/($E$11*E17*0.000001/$E$12)*$H$14 | I17: =$E$9/F17*$I$14
B18: 325.0157 | C18: 18.358616 | E18: 329.47986 | F18: 17.687658 | G18: =$E$11/($E$5*$E$12*E18*0.000001) | H18: =$E$9*0.001/($E$11*E18*0.000001/$E$12)*$H$14 | I18: =$E$9/F18*$I$14
B19: 442.5608 | C19: 26.270922 | E19: 431.1312 | F19: 18.208508 | G19: =$E$11/($E$5*$E$12*E19*0.000001) | H19: =$E$9*0.001/($E$11*E19*0.000001/$E$12)*$H$14 | I19: =$E$9/F19*$I$14
B20: 493.5383 | C20: 30.813509 | E20: 459.33105 | F20: 22.74727 | G20: =$E$11/($E$5*$E$12*E20*0.000001) | H20: =$E$9*0.001/($E$11*E20*0.000001/$E$12)*$H$14 | I20: =$E$9/F20*$I$14
B21: 499.98764 | C21: 38.203377 | E21: 507.54565 | F21: 26.785614 | G21: =$E$11/($E$5*$E$12*E21*0.000001) | H21: =$E$9*0.001/($E$11*E21*0.000001/$E$12)*$H$14 | I21: =$E$9/F21*$I$14
B22: 606.64636 | C22: 38.47318 | E22: 590.70447 | F22: 32.719 | G22: =$E$11/($E$5*$E$12*E22*0.000001) | H22: =$E$9*0.001/($E$11*E22*0.000001/$E$12)*$H$14 | I22: =$E$9/F22*$I$14
B23: 671.8362 | C23: 50.91072 | E23: 707.3854 | F23: 32.234818 | G23: =$E$11/($E$5*$E$12*E23*0.000001) | H23: =$E$9*0.001/($E$11*E23*0.000001/$E$12)*$H$14 | I23: =$E$9/F23*$I$14
B24: 828.2255 | C24: 60.34089 | E24: 838.92175 | F24: 36.664986 | G24: =$E$11/($E$5*$E$12*E24*0.000001) | H24: =$E$9*0.001/($E$11*E24*0.000001/$E$12)*$H$14 | I24: =$E$9/F24*$I$14
B25: 863.2735 | C25: 58.709488 | E25: 850.64764 | F25: 34.651833 | G25: =$E$11/($E$5*$E$12*E25*0.000001) | H25: =$E$9*0.001/($E$11*E25*0.000001/$E$12)*$H$14 | I25: =$E$9/F25*$I$14
B26: 1097.7465 | C26: 76.63308 | E26: 1142.1499 | F26: 40.242374 | G26: =$E$11/($E$5*$E$12*E26*0.000001) | H26: =$E$9*0.001/($E$11*E26*0.000001/$E$12)*$H$14 | I26: =$E$9/F26*$I$14
B27: 1210.7236 | C27: 88.74279 | E27: 1360.3489 | F27: 44.81304 | G27: =$E$11/($E$5*$E$12*E27*0.000001) | H27: =$E$9*0.001/($E$11*E27*0.000001/$E$12)*$H$14 | I27: =$E$9/F27*$I$14
E28: 271.49048 | F28: 18.882217 | G28: =$E$11/($E$5*$E$12*E28*0.000001) | H28: =$E$9*0.001/($E$11*E28*0.000001/$E$12)*$H$14 | I28: =$E$9/F28*$I$14
E29: 465.45264 | F29: 30.215885 | G29: =$E$11/($E$5*$E$12*E29*0.000001) | H29: =$E$9*0.001/($E$11*E29*0.000001/$E$12)*$H$14 | I29: =$E$9/F29*$I$14
E30: 649.7061 | F30: 41.5482 | G30: =$E$11/($E$5*$E$12*E30*0.000001) | H30: =$E$9*0.001/($E$11*E30*0.000001/$E$12)*$H$14 | I30: =$E$9/F30*$I$14
E31: 1052.3977 | F31: 53.329765 | G31: =$E$11/($E$5*$E$12*E31*0.000001) | H31: =$E$9*0.001/($E$11*E31*0.000001/$E$12)*$H$14 | I31: =$E$9/F31*$I$14
E32: 1367.7031 | F32: 65.5179 | G32: =$E$11/($E$5*$E$12*E32*0.000001) | H32: =$E$9*0.001/($E$11*E32*0.000001/$E$12)*$H$14 | I32: =$E$9/F32*$I$14
E33: 1620.0197 | F33: 71.415794 | G33: =$E$11/($E$5*$E$12*E33*0.000001) | H33: =$E$9*0.001/($E$11*E33*0.000001/$E$12)*$H$14 | I33: =$E$9/F33*$I$14
E34: 1920.864 | F34: 78.15799 | G34: =$E$11/($E$5*$E$12*E34*0.000001) | H34: =$E$9*0.001/($E$11*E34*0.000001/$E$12)*$H$14 | I34: =$E$9/F34*$I$14
E35: 2338.1267 | F35: 89.52283 | G35: =$E$11/($E$5*$E$12*E35*0.000001) | H35: =$E$9*0.001/($E$11*E35*0.000001/$E$12)*$H$14 | I35: =$E$9/F35*$I$14
E36: 2847.677 | F36: 97.96921 | G36: =$E$11/($E$5*$E$12*E36*0.000001) | H36: =$E$9*0.001/($E$11*E36*0.000001/$E$12)*$H$14 | I36: =$E$9/F36*$I$14
A49: Model | B49: FENE-P | F49: C2D2
A51: Nk | B51: 30000 | F51: 30000
A52: Oh | B52: Inf | F52: Inf
C53: Wi_e | F53: Wi_e
...

Sheet Aisling sandbox

Sheet Calabrese_sandbox
A1: PS in DOP
B2: 7M | H2: 16M
A3: Mw | B3: 6870000 | C3: 6870000 | D3: 6870000 | E3: 6870000 | F3: 6870000 | G3: 6870000 | H3: 16165000 | I3: 16165000 | J3: 16165000 | K3: 16165000 | L3: 16165000 | M3: 16165000
A4: NK | B4: =B3/742 | C4: =C3/742 | D4: =D3/742 | E4: =E3/742 | F4: =F3/742 | G4: =G3/742 | H4: =H3/742 | I4: =I3/742 | ... M4: =M3/742
A5: c (w% = g/100 g) | B5: =200/1000000*100 | C5: =200/1000000*100 | D5: =200/1000000*100 | E5: =500/1000000*100 | F5: =500/1000000*100 | G5: =500/1000000*100 | H5: =50/1000000*100 | I5: =50/1000000*100 | J5: =50/1000000*100 | K5: =100/1000000*100 | L5: =100/1000000*100 | M5: =100/1000000*100
A6: rho (kg/cu.m) | B6: 981 | C6: 981 | D6: 981 | E6: 981 | F6: 981 | G6: 981 | H6: 981 | I6: 981 | J6: 981 | K6: 981 | L6: 981 | M6: 981
A7: c (g/cu.m) | B7: =B5/100*B6*1000 | C7: =C5/100*C6*1000 | D7: =D5/100*D6*1000 | E7: =E5/100*E6*1000 | F7: =F5/100*F6*1000 | G7: =G5/100*G6*1000 | H7: =H5/100*H6*1000 | I7: =I5/100*I6*1000 | ... M7: =M5/100*M6*1000
A8: c/c* | B8: =B7/B3*6.023E+23*(0.0000000018*B4^0.5)^3 | C8: =C7/C3*6.023E+23*(0.0000000018*C4^0.5)^3 | D8: =D7/D3*6.023E+23*(0.0000000018*D4^0.5)^3 | E8: =E7/E3*6.023E+23*(0.0000000018*E4^0.5)^3 | F8: =F7/F3*6.023E+23*(0.0000000018*F4^0.5)^3 | G8: =G7/G3*6.023E+23*(0.0000000018*G4^0.5)^3 | H8: =H7/H3*6.023E+23*(0.0000000018*H4^0.5)^3 | I8: =I7/I3*6.023E+23*(0.0000000018*I4^0.5)^3 | ... M8: =M7/M3*6.023E+23*(0.0000000018*M4^0.5)^3
A9: eta_s (Pas) | B9: 0.057 | C9: 0.057 | D9: 0.057 | E9: 0.057 | F9: 0.057 | G9: 0.057 | H9: 0.057 | I9: 0.057 | J9: 0.057 | K9: 0.057 | L9: 0.057 | M9: 0.057
A10: sigma (N/m) | B10: 0.031 | C10: 0.031 | D10: 0.031 | E10: 0.031 | F10: 0.031 | G10: 0.031 | H10: 0.031 | I10: 0.031 | J10: 0.031 | K10: 0.031 | L10: 0.031 | M10: 0.031
A11: eta_0 (Pa s) | B11: 0.059 | C11: 0.059 | D11: 0.059 | E11: 0.062 | F11: 0.062 | G11: 0.062
A12: eta_p (Pa s) | B12: =B11-B9 | C12: =C11-C9 | D12: =D11-D9 | E12: =E11-E9 | F12: =F11-F9 | G12: =G11-G9
A13: lambda_eta (s) | B13: =B12/(B7/B3*6.023E+23*1.381E-23*298) | C13: =C12/(C7/C3*6.023E+23*1.381E-23*298) | D13: =D12/(D7/D3*6.023E+23*1.381E-23*298) | E13: =E12/(E7/E3*6.023E+23*1.381E-23*298) | F13: =F12/(F7/F3*6.023E+23*1.381E-23*298) | G13: =G12/(G7/G3*6.023E+23*1.381E-23*298) | H13: =$E13*(H3/$E3)^1.5 | I13: =$E13*(I3/$E3)^1.5 | J13: =$E13*(J3/$E3)^1.5 | K13: =$E13*(K3/$E3)^1.5 | L13: =$E13*(L3/$E3)^1.5 | M13: =$E13*(M3/$E3)^1.5
A14: lambda_1 (s) | B14: =B13/1.835 | C14: =C13/1.835 | D14: =D13/1.835 | E14: =E13/1.835 | F14: =F13/1.835 | G14: =G13/1.835 | H14: =H13/1.835 | I14: =I13/1.835 | ... M14: =M13/1.835
A15: R0 (mm) | B15: =C15/3*2 | C15: 0.5 | D15: =C15/3*4 | E15: =F15/3*2 | F15: 0.5 | G15: =F15/3*4 | H15: =I15/3*2 | I15: 0.5 | J15: =I15/3*4 | K15: =L15/3*2 | L15: 0.5 | M15: =L15/3*4
A16: lambda_v (s) | B16: =B9*B15/B10/1000 | C16: =C9*C15/C10/1000 | D16: =D9*D15/D10/1000 | E16: =E9*E15/E10/1000 | F16: =F9*F15/F10/1000 | G16: =G9*G15/G10/1000 | H16: =H9*H15/H10/1000 | I16: =I9*I15/I10/1000 | ... M16: =M9*M15/M10/1000
A17: De_v | B17: =B14/B16 | C17: =C14/C16 | D17: =D14/D16 | E17: =E14/E16 | F17: =F14/F16 | G17: =G14/G16 | H17: =H14/H16 | I17: =I14/I16 | ... M17: =M14/M16
A18: lambda_eta/lambda_1 | B18: =B13/B14 | C18: =C13/C14 | D18: =D13/D14 | E18: =E13/E14 | F18: =F13/F14 | G18: =G13/G14 | H18: =H13/H14 | I18: =I13/I14 | ... M18: =M13/M14
A19: lambda_e(s) | B19: 0.016 | C19: 0.018 | D19: 0.018 | E19: 0.028 | F19: 0.028 | G19: 0.028 | H19: 0.045 | I19: 0.048 | J19: 0.047 | K19: 0.068 | L19: 0.078 | M19: 0.077
A20: strain rate (1/s) | B20: =2/(3*B19) | C20: =2/(3*C19) | D20: =2/(3*D19) | E20: =2/(3*E19) | F20: =2/(3*F19) | G20: =2/(3*G19) | H20: =2/(3*H19) | I20: =2/(3*I19) | ... M20: =2/(3*M19)
A21: Wi_e | B21: =B20*B14 | C21: =C20*C14 | D21: =D20*D14 | E21: =E20*E14 | F21: =F20*F14 | G21: =G20*G14 | H21: =H20*H14 | I21: =I20*I14 | ... M21: =M20*M14
A22: [eta] ml/g
A23: c/c*_KM
B26: 25.121001 | C26: 0.64153095 | E26: 25.121001 | F26: 0.36658911 | H26: 90.670374 | I26: 0.82329133 | K26: 90.670374 | L26: 0.54482514
B27: 16.747334 | C27: 0.57024973 | E27: 16.747334 | F27: 0.36658911 | H27: 60.446916 | I27: 0.77183562 | K27: 60.446916 | L27: 0.47497577
B28: 12.560501 | C28: 0.57024973 | E28: 12.560501 | F28: 0.36658911 | H28: 45.335187 | I28: 0.78825765 | K28: 45.335187 | L28: 0.48114428

Sheet Plan_Generic
A1: enabled | B1: sweep_id | C1: flow_type | D1: NK | E1: hK_star | F1: fe_model | G1: drag_model | H1: phi | I1: De | J1: Oh | K1: XR | L1: folder | M1: out_root | N1: notes
A2: FALSE | B2: 1 | C2: styext | D2: 3000 | E2: 0.05 | F2: fenepm | G2: constant | H2: 0.5 | I2: 1 | M2: tnwpaper/outputs/generic_behaviour
A3: FALSE | B3: 2 | C3: styext | D3: 3000 | E3: 0.05 | F3: fenepm | G3: c2d2 | H3: 0.5 | I3: 1 | M3: tnwpaper/outputs/generic_behaviour
A4: FALSE | B4: 3 | C4: caber | D4: 3000 | E4: 0.05 | F4: fenepm | G4: constant | H4: [0.01, 0.1, 0.5, 1] | I4: [0.01, 0.03, 0.1, 0.3, 1, 3, 10, 30, 100] | M4: tnwpaper/outputs/generic_behaviour
A5: FALSE | B5: 4 | C5: caber | D5: 3000 | E5: 0.05 | F5: fenepm | G5: c2d2 | H5: [0.01, 0.1, 0.5, 1] | I5: [0.01, 0.03, 0.1, 0.3, 1, 3, 10, 30, 100] | M5: tnwpaper/outputs/generic_behaviour
A6: FALSE | B6: 5 | C6: styext | D6: 10000 | E6: 0.05 | F6: fenepm | G6: constant | H6: 0.1 | I6: 1 | M6: tnwpaper/outputs/generic_behaviour | N6: Effect of NK - large NK
A7: FALSE | B7: 6 | C7: styext | D7: 10000 | E7: 0.05 | F7: fenepm | G7: c2d2 | H7: 0.1 | I7: 1 | M7: tnwpaper/outputs/generic_behaviour | N7: Effect of NK - large NK
A8: FALSE | B8: 7 | C8: caber | D8: 10000 | E8: 0.05 | F8: fenepm | G8: constant | H8: 0.1 | I8: [0.01, 0.03, 0.1, 0.3, 1, 3, 10, 30, 100] | M8: tnwpaper/outputs/generic_behaviour | N8: Effect of NK - large NK
A9: FALSE | B9: 8 | C9: caber | D9: 10000 | E9: 0.05 | F9: fenepm | G9: c2d2 | H9: 0.1 | I9: [0.01, 0.03, 0.1, 0.3, 1, 3, 10, 30, 100] | M9: tnwpaper/outputs/generic_behaviour | N9: Effect of NK - large NK
A10: FALSE | B10: 9 | C10: styext | D10: 1000 | E10: 0.05 | F10: fenepm | G10: constant | H10: 0.1 | I10: 1 | M10: tnwpaper/outputs/generic_behaviour | N10: Effect of NK - small NK
A11: FALSE | B11: 10 | C11: styext | D11: 1000 | E11: 0.05 | F11: fenepm | G11: c2d2 | H11: 0.1 | I11: 1 | M11: tnwpaper/outputs/generic_behaviour | N11: Effect of NK - small NK
A12: FALSE | B12: 11 | C12: caber | D12: 1000 | E12: 0.05 | F12: fenepm | G12: constant | H12: 0.1 | I12: [0.01, 0.03, 0.1, 0.3, 1, 3, 10, 30, 100] | M12: tnwpaper/outputs/generic_behaviour | N12: Effect of NK - small NK
A13: FALSE | B13: 12 | C13: caber | D13: 1000 | E13: 0.05 | F13: fenepm | G13: c2d2 | H13: 0.1 | I13: [0.01, 0.03, 0.1, 0.3, 1, 3, 10, 30, 100] | M13: tnwpaper/outputs/generic_behaviour | N13: Effect of NK - small NK
A14: FALSE | B14: 13 | C14: styext | D14: 3000 | E14: 0.25 | F14: fenepm | G14: constant | H14: 0.1 | I14: 1 | M14: tnwpaper/outputs/generic_behaviour | N14: Effect of hK_star - large hK_star
A15: FALSE | B15: 14 | C15: styext | D15: 3000 | E15: 0.25 | F15: fenepm | G15: c2d2 | H15: 0.1 | I15: 1 | M15: tnwpaper/outputs/generic_behaviour | N15: Effect of hK_star - large hK_star
A16: FALSE | B16: 15 | C16: caber | D16: 3000 | E16: 0.25 | F16: fenepm | G16: constant | H16: 0.1 | I16: [0.01, 0.03, 0.1, 0.3, 1, 3, 10, 30, 100] | M16: tnwpaper/outputs/generic_behaviour | N16: Effect of hK_star - large hK_star
A17: FALSE | B17: 16 | C17: caber | D17: 3000 | E17: 0.25 | F17: fenepm | G17: c2d2 | H17: 0.1 | I17: [0.01, 0.03, 0.1, 0.3, 1, 3, 10, 30, 100] | M17: tnwpaper/outputs/generic_behaviour | N17: Effect of hK_star - large hK_star
A18: FALSE | B18: 17 | C18: styext | D18: 3000 | E18: 0.025 | F18: fenepm | G18: constant | H18: 0.1 | I18: 1 | M18: tnwpaper/outputs/generic_behaviour | N18: Effect of hK_star -small hK_star
A19: FALSE | B19: 18 | C19: styext | D19: 3000 | E19: 0.025 | F19: fenepm | G19: c2d2 | H19: 0.1 | I19: 1 | M19: tnwpaper/outputs/generic_behaviour | N19: Effect of hK_star -small hK_star
A20: FALSE | B20: 19 | C20: caber | D20: 3000 | E20: 0.025 | F20: fenepm | G20: constant | H20: 0.1 | I20: [0.01, 0.03, 0.1, 0.3, 1, 3, 10, 30, 100] | M20: tnwpaper/outputs/generic_behaviour | N20: Effect of hK_star -small hK_star
A21: FALSE | B21: 20 | C21: caber | D21: 3000 | E21: 0.025 | F21: fenepm | G21: c2d2 | H21: 0.1 | I21: [0.01, 0.03, 0.1, 0.3, 1, 3, 10, 30, 100] | M21: tnwpaper/outputs/generic_behaviour | N21: Effect of hK_star -small hK_star
A22: TRUE | B22: 21 | C22: styext | D22: 3000 | E22: 0.05 | F22: fenepm | G22: constant | H22: 0.5 | I22: 1 | J22: 0.01 | K22: 0.51 | L22: generic_inertial_oh0p01 | M22: tnwpaper/outputs/generic_behaviour | N22: inertial fig Oh=0.01 (styext steady-state curve)
A23: TRUE | B23: 22 | C23: styext | D23: 3000 | E23: 0.05 | F23: fenepm | G23: c2d2 | H23: [0.01, 0.1, 0.5, 1] | I23: 1 | J23: 0.01 | K23: 0.51 | L23: generic_inertial_oh0p01 | M23: tnwpaper/outputs/generic_behaviour | N23: styext steady-state curve, c2d2 drag (phi-dependent)
A24: TRUE | B24: 23 | C24: caber_inertial | D24: 3000 | E24: 0.05 | F24: fenepm | G24: constant | H24: [0.01, 0.1, 0.5, 1] | I24: [0.01, 0.03, 0.1, 0.3, 1, 3, 10, 30, 100] | J24: 0.01 | K24: 0.51 | L24: generic_inertial_oh0p01 | M24: tnwpaper/outputs/generic_behaviour | N24: inertial fig Oh=0.01, constant drag
A25: TRUE | B25: 24 | C25: caber_inertial | D25: 3000 | E25: 0.05 | F25: fenepm | G25: c2d2 | H25: [0.01, 0.1, 0.5, 1] | I25: [0.01, 0.03, 0.1, 0.3, 1, 3, 10, 30, 100] | J25: 0.01 | K25: 0.51 | L25: generic_inertial_oh0p01 | M25: tnwpaper/outputs/generic_behaviour | N25: inertial fig Oh=0.01, c2d2 drag

Sheet Plan_Prestretch
A1: enabled | B1: sweep_id | C1: flow_type | D1: NK | E1: hK_star | F1: fe_model | G1: drag_model | H1: phi | I1: De | J1: initial_micro_affine_strain | K1: folder | L1: out_root | M1: notes
A2: FALSE | B2: 1 | C2: caber | D2: 3000 | E2: 0.05 | F2: fenepm | G2: constant | H2: [0.01, 0.1, 0.5, 1] | I2: [0.01, 0.03, 0.1, 0.3, 1, 3, 10, 30, 100] | J2: 0 | L2: tnwpaper/outputs/prestretch_test/epre_0p0
A3: FALSE | B3: 2 | C3: caber | D3: 3000 | E3: 0.05 | F3: fenepm | G3: c2d2 | H3: [0.01, 0.1, 0.5, 1] | I3: [0.01, 0.03, 0.1, 0.3, 1, 3, 10, 30, 100] | J3: 0 | L3: tnwpaper/outputs/prestretch_test/epre_0p0
A4: FALSE | B4: 3 | C4: caber | D4: 3000 | E4: 0.05 | F4: fenepm | G4: constant | H4: [0.01, 0.1, 0.5, 1] | I4: [0.01, 0.03, 0.1, 0.3, 1, 3, 10, 30, 100] | J4: 0.1 | L4: tnwpaper/outputs/prestretch_test/epre_0p1
A5: FALSE | B5: 4 | C5: caber | D5: 3000 | E5: 0.05 | F5: fenepm | G5: c2d2 | H5: [0.01, 0.1, 0.5, 1] | I5: [0.01, 0.03, 0.1, 0.3, 1, 3, 10, 30, 100] | J5: 0.1 | L5: tnwpaper/outputs/prestretch_test/epre_0p1
A6: TRUE | B6: 5 | C6: caber | D6: 3000 | E6: 0.05 | F6: fenepm | G6: constant | H6: [0.01, 0.1, 0.5, 1] | I6: [0.01, 0.03, 0.1, 0.3, 1, 3, 10, 30, 100] | J6: 0.5 | L6: tnwpaper/outputs/prestretch_test/epre_0p5
A7: TRUE | B7: 6 | C7: caber | D7: 3000 | E7: 0.05 | F7: fenepm | G7: c2d2 | H7: [0.01, 0.1, 0.5, 1] | I7: [0.01, 0.03, 0.1, 0.3, 1, 3, 10, 30, 100] | J7: 0.5 | L7: tnwpaper/outputs/prestretch_test/epre_0p5
A8: TRUE | B8: 7 | C8: caber | D8: 3000 | E8: 0.05 | F8: fenepm | G8: constant | H8: [0.01, 0.1, 0.5, 1] | I8: [0.01, 0.03, 0.1, 0.3, 1, 3, 10, 30, 100] | J8: 1 | L8: tnwpaper/outputs/prestretch_test/epre_1p0
A9: TRUE | B9: 8 | C9: caber | D9: 3000 | E9: 0.05 | F9: fenepm | G9: c2d2 | H9: [0.01, 0.1, 0.5, 1] | I9: [0.01, 0.03, 0.1, 0.3, 1, 3, 10, 30, 100] | J9: 1 | L9: tnwpaper/outputs/prestretch_test/epre_1p0

Sheet Sheet1
